# Введение

`zio` предоставляет `zio.App`, похожий на `IOApp` из cats:

```scala
import java.io.IOException

import zio.{ExitCode, ZIO}
import zio.console._

object Main extends zio.App {

  override def run(args: List[String]): ZIO[zio.ZEnv, Nothing, ExitCode] =
    myAppLogic.exitCode

  val myAppLogic: ZIO[Console, IOException, Unit] =
    for {
      _    <- putStrLn("Hello")
      name <- getStrLn
      _    <- putStrLn(s"Hello, $name")
    } yield ()
}
```

Метод run должен вернуть `ZIO` с обработанными исключениями, поэтому сам `ZIO` будет иметь тип исключений `Nothing`. В понятиях ZIO это называется *unexceptional ZIO value*.

Один из путей достичь этого - воспользоваться функцией `fold` и предоставить две функции - `eh: E => B` и `ah: A => B`. Первая делает из ошибки тип `B`, вторая из успешного ответа. Именно это и делает под капотом `exitCode`, приводя любой из результатов `myAppLogic` к типу `B` - `ExitCode`:

```scala
/**
  * Maps this effect to the default exit codes.
  */
final def exitCode: URIO[R with console.Console, ExitCode] =
  self.foldCauseM(
    cause => console.putStrLn(cause.prettyPrint) as ExitCode.failure,
    _ => ZIO.succeedNow(ExitCode.success)
  )
```

Смысл этого метода в том, чтобы вернуть 0 при успешном выполнении и 1 при неудаче.


# Источник

https://zio.dev/docs/getting_started.html
